Traceback (most recent call last):
  File "/opt/more/anaconda3/lib/python3.7/site-packages/jupyter_cache/executors/basic.py", line 157, in execute
    executenb(nb_bundle.nb, cwd=tmpdirname)
  File "/opt/more/anaconda3/lib/python3.7/site-packages/nbconvert/preprocessors/execute.py", line 737, in executenb
    return ep.preprocess(nb, resources, km=km)[0]
  File "/opt/more/anaconda3/lib/python3.7/site-packages/nbconvert/preprocessors/execute.py", line 405, in preprocess
    nb, resources = super(ExecutePreprocessor, self).preprocess(nb, resources)
  File "/opt/more/anaconda3/lib/python3.7/site-packages/nbconvert/preprocessors/base.py", line 69, in preprocess
    nb.cells[index], resources = self.preprocess_cell(cell, resources, index)
  File "/opt/more/anaconda3/lib/python3.7/site-packages/nbconvert/preprocessors/execute.py", line 448, in preprocess_cell
    raise CellExecutionError.from_cell_and_msg(cell, out)
nbconvert.preprocessors.execute.CellExecutionError: An error occurred while executing the following cell:
------------------
quality = read.csv("/home/jerrywang/GitHub/note_viajupyterbook/mynote/datas/Diabetes.csv")
str(quality)
------------------

Error in file(file, "rt"): 无法打开链结
Traceback:

1. read.csv("/home/jerrywang/GitHub/note_viajupyterbook/mynote/datas/Diabetes.csv")
2. read.table(file = file, header = header, sep = sep, quote = quote, 
 .     dec = dec, fill = fill, comment.char = comment.char, ...)
3. file(file, "rt")
ERROR: Error in file(file, "rt"): 无法打开链结


